Workbook

Sheet CONSOLIDATED SUMMARY
A1: ORLEANS PARISH ASSESSOR'S OFFICE
A2: SUPPLEMENTAL TAX ROLLS SUMMARY
A3: ="CALENDAR YEAR " & YEAR(TODAY()) & " - QUARTER 2" -> CALENDAR YEAR 2026 - QUARTER 2
A4: ="TAX YEARS " & (YEAR(TODAY()) - 3) & " TO " & YEAR(TODAY()) -> TAX YEARS 2023 TO 2026
A5: ="AS OF " & UPPER(TEXT(TODAY(), "mmmm d, yyyy")) -> AS OF AUGUST 19, 2026
B7: TAX YEAR
B8: =YEAR(TODAY()) -> 2026 | C8: =YEAR(TODAY()) - 1 -> 2025 | D8: =YEAR(TODAY()) - 2 -> 2024 | E8: =YEAR(TODAY()) - 3 -> 2023 | F8: Total
A9: REAL ESTATE (INCREASE) | B9: ='REAL PROPERTY DETAILS'!U160 -> 1037140 | C9: ='REAL PROPERTY DETAILS'!U72 -> 383830 | D9: ='REAL PROPERTY DETAILS'!U38 -> 466690 | E9: ='REAL PROPERTY DETAILS'!U16 -> 125100 | F9: =SUM(B9:E9) -> 2012760
A10: PERSONAL PROPERTY (INCREASE) | B10: ='PP DETAILS'!J12 -> 31940 | C10: ='PP DETAILS'!J9 -> 26620 | D10: ='PP DETAILS'!J6 -> 0 | E10: ='PP DETAILS'!J3 -> 0 | F10: =SUM(B10:E10) -> 58560
A11: PUBLIC SERVICE ROLLS | B11: 0 | C11: 0 | D11: 0 | E11: 0 | F11: 0
A12: TOTAL NET ASSESSMENT INCREASE | B12: =SUM(B9:B11) -> 1069080 | C12: =SUM(C9:C11) -> 410450 | D12: =SUM(D9:D11) -> 466690 | E12: =SUM(E9:E11) -> 125100 | F12: =SUM(B12:E12) -> 2071320
A13: HOMESTEAD EXEMPTION NET DECREASE | B13: ='REAL PROPERTY DETAILS'!V160 -> -485820 | C13: ='REAL PROPERTY DETAILS'!V72 -> -172390 | D13: ='REAL PROPERTY DETAILS'!V38 -> -78510 | E13: ='REAL PROPERTY DETAILS'!V16 -> -62420 | F13: =SUM(B13:E13) -> -799140
A14: NET TOTAL ASSESSMENT INCREASE | B14: =SUM(B12,ABS(B13)) -> 1554900 | C14: =SUM(C12,ABS(C13)) -> 582840 | D14: =SUM(D12,ABS(D13)) -> 545200 | E14: =SUM(E12,ABS(E13)) -> 187520 | F14: =SUM(B14:E14) -> 2870460

Sheet REAL PROPERTY DETAILS
A1: PARID | B1: ALTID | C1: TAXYR | D1: OWN1 | E1: ROLLTYPE | F1: LUC | G1: DMG_FLAG | H1: ASMT_FLAG | I1: OLD_LAND | J1: OLD_BLDG | K1: OLD_TOTAL_ASMT | L1: OLD EXEMPT | M1: OLD NET ASMT | N1: OLD_HOMESTEAD | O1: NEW_LAND | P1: NEW_BLDG | Q1: NEW_TOTAL_ASMT | R1: NEW EXEMPT | S1: NEW NETASMT | T1: NEW_HOMESTEAD | U1: TOTAL_ASMT_DIFF | V1: HOMESTEAD_DIFF
A2: 14575-MICHOUDBL | B2: 39W909566 | C2: 2023 | D2: MR. JOHN CUMMINGS III | E2: REAL | I2: 0 | J2: 0 | K2: 0 | N2: 0 | O2: 14940 | P2: 0 | Q2: 14940 | T2: 0 | U2: 14940 | V2: 0
A3: 3728-VINCENNESPL | B3: 615109602 | C3: 2023 | D3: EST. OF MRS. AGATHA F. SUNSERI, C/O MS. A. G. VIDRINE, ET AL | E3: REAL | F3: 510 | I3: 1630 | J3: 3750 | K3: 5380 | N3: 5380 | O3: 6120 | P3: 26890 | Q3: 33010 | T3: 0 | U3: 27630 | V3: -5380
A4: 1646-STANDREWST | B4: 412106107 | C4: 2023 | D4: MR. ALLEN BORNE | E4: REAL | F4: 510 | I4: 3130 | J4: 20710 | K4: 23840 | N4: 7500 | O4: 4690 | P4: 22140 | Q4: 26830 | T4: 0 | U4: 2990 | V4: -7500
A5: 2432-DELACHAISEST | B5: 614325503 | C5: 2023 | D5: MR. & MRS. ALVIN BATISTE SR. | E5: REAL | F5: 510 | I5: 1210 | J5: 1810 | K5: 3020 | N5: 3020 | O5: 1680 | P5: 13900 | Q5: 15580 | T5: 0 | U5: 12560 | V5: -3020
A6: 8226-APPLEST | B6: 716321718 | C6: 2023 | D6: EST. OF MR. BRADDOCK CHAMBLISS | E6: REAL | F6: 520 | I6: 2300 | J6: 9350 | K6: 11650 | N6: 7500 | O6: 2300 | P6: 11300 | Q6: 13600 | T6: 0 | U6: 1950 | V6: -7500
A7: 1033-ALVARST | B7: 39W206322 | C7: 2023 | D7: MRS. JEAN A. LOUIS & EST. OF MS. HAZEL L. BERRYHILL | E7: REAL | F7: 520 | I7: 4050 | J7: 10950 | K7: 15000 | N7: 7500 | O7: 6100 | P7: 17400 | Q7: 23500 | T7: 3750 | U7: 8500 | V7: -3750
A8: 1525-NDERBIGNYST | B8: 37W109008 | C8: 2023 | D8: EST. OF MRS. MARIE S. HENO, ET AL | E8: REAL | F8: 510 | I8: 440 | J8: 2230 | K8: 2670 | N8: 2670 | O8: 2200 | P8: 6510 | Q8: 8710 | T8: 0 | U8: 6040 | V8: -2670
A9: 11260-NOTAWAYLN | B9: 39W086006 | C9: 2023 | D9: MR. & MRS. RICHARD G. BUSH | E9: REAL | F9: 510 | I9: 2200 | J9: 8300 | K9: 10500 | N9: 7500 | O9: 3670 | P9: 13410 | Q9: 17080 | T9: 7500 | U9: 6580 | V9: 0
A10: 9756-WROCKTONCR | B10: 39W043614 | C10: 2023 | D10: EST. OF MS. SHIRLEY I. BURNS BRISCOE | E10: REAL | F10: 510 | I10: 2520 | J10: 11080 | K10: 13600 | N10: 7500 | O10: 1680 | P10: 13670 | Q10: 15350 | T10: 0 | U10: 1750 | V10: -7500
A11: 2732-LAVENDERST | B11: 38W304907 | C11: 2023 | D11: EST. OF MRS. ALEIDA RAMIREZ VALDEZ, ET AL | E11: REAL | F11: 510 | I11: 630 | J11: 5870 | K11: 6500 | N11: 6500 | O11: 1440 | P11: 11210 | Q11: 12650 | T11: 0 | U11: 6150 | V11: -6500
A12: 2819-STANTHONYST | B12: 37W306224 | C12: 2023 | D12: EST. OF THE W & W MILES IRREVOCABLE R.E. TRUST | E12: REAL | F12: 510 | I12: 1020 | J12: 5480 | K12: 6500 | N12: 6500 | O12: 1020 | P12: 10780 | Q12: 11800 | T12: 0 | U12: 5300 | V12: -6500
A13: 2215-APTUREAUDAV | B13: 37W204419 | C13: 2023 | D13: EST. OF MR. & MRS. HARRISON BRIGHT | E13: REAL | F13: 520 | I13: 790 | J13: 7710 | K13: 8500 | N13: 7500 | O13: 790 | P13: 10750 | Q13: 11540 | T13: 0 | U13: 3040 | V13: -7500
A14: 14570-MICHOUDBL | B14: 39W965140 | C14: 2023 | D14: MR. JOHN CUMMINGS III | E14: REAL | I14: 0 | J14: 0 | K14: 0 | N14: 0 | O14: 20290 | P14: 0 | Q14: 20290 | T14: 0 | U14: 20290 | V14: 0
A15: 821-STMAURICEAV | B15: 39W110603 | C15: 2023 | D15: EST. OF MS. JEANETTE T. WILLIAMS, C/O ANTOINETTE V. WILLIAMS | E15: REAL | F15: 510 | I15: 350 | J15: 4250 | K15: 4600 | N15: 4600 | O15: 1510 | P15: 10470 | Q15: 11980 | T15: 0 | U15: 7380 | V15: -4600
A16: Total | I16: =SUM(I2:I15) -> 20270 | J16: =SUM(J2:J15) -> 91490 | K16: =SUM(K2:K15) -> 111760 | N16: =SUM(N2:N15) -> 73670 | O16: =SUM(O2:O15) -> 68430 | P16: =SUM(P2:P15) -> 168430 | Q16: =SUM(Q2:Q15) -> 236860 | T16: =SUM(T2:T15) -> 11250 | U16: =SUM(U2:U15) -> 125100 | V16: =SUM(V2:V15) -> -62420 | W16: Total | X16: =U16-V16 -> 187520
A19: 3728-VINCENNESPL | B19: 615109602 | C19: 2024 | D19: EST. OF MRS. AGATHA F. SUNSERI, C/O MS. A. G. VIDRINE, ET AL | E19: REAL | F19: 510 | I19: 1630 | J19: 3750 | K19: 5380 | N19: 5380 | O19: 8160 | P19: 26800 | Q19: 34960 | T19: 0 | U19: 29580 | V19: -5380
A20: 2432-DELACHAISEST | B20: 614325503 | C20: 2024 | D20: MR. & MRS. ALVIN BATISTE SR. | E20: REAL | F20: 510 | I20: 1210 | J20: 1810 | K20: 3020 | N20: 3020 | O20: 4210 | P20: 12090 | Q20: 16300 | T20: 0 | U20: 13280 | V20: -3020
A21: 2668-MERCEDESBL | B21: 513708341 | C21: 2024 | D21: MR. DARRELL H. RICHARDS | E21: REAL | F21: 510 | I21: 1130 | J21: 5970 | K21: 7100 | N21: 0 | O21: 2250 | P21: 7290 | Q21: 9540 | T21: 0 | U21: 2440 | V21: 0
A22: 1646-STANDREWST | B22: 412106107 | C22: 2024 | D22: MR. ALLEN BORNE | E22: REAL | F22: 510 | I22: 3130 | J22: 20710 | K22: 23840 | N22: 7500 | O22: 7820 | P22: 22750 | Q22: 30570 | T22: 0 | U22: 6730 | V22: -7500
A23: 1901-ROUSSEAUST | B23: 411102503 | C23: 2024 | D23: WAL-MART REAL ESTATE BUSINESS TRUST | E23: REAL | F23: 930 | I23: 251960 | J23: 0 | K23: 251960 | L23: 251960 | M23: =K23-L23 -> 0 | N23: 0 | O23: 251960 | P23: 0 | Q23: 251960 | R23: 0 | S23: =Q23-R23 -> 251960 | T23: 0 | U23: =S23-M23 -> 251960 | V23: 0
A24: 14570-MICHOUDBL | B24: 39W965140 | C24: 2024 | D24: MR. JOHN CUMMINGS III | E24: REAL | I24: 0 | J24: 0 | K24: 0 | N24: 0 | O24: 20290 | P24: 0 | Q24: 20290 | T24: 0 | U24: 20290 | V24: 0
A25: 14575-MICHOUDBL | B25: 39W909566 | C25: 2024 | D25: MR. JOHN CUMMINGS III | E25: REAL | I25: 0 | J25: 0 | K25: 0 | N25: 0 | O25: 14940 | P25: 0 | Q25: 14940 | T25: 0 | U25: 14940 | V25: 0
A26: 1237-TRICOUST | B26: 39W300101 | C26: 2024 | D26: MS. DIANE H. WILLIAMS | E26: REAL | F26: 510 | I26: 970 | J26: 6710 | K26: 7680 | N26: 7500 | O26: 1920 | P26: 9890 | Q26: 11810 | T26: 0 | U26: 4130 | V26: -7500
A27: 1033-ALVARST | B27: 39W206322 | C27: 2024 | D27: MRS. JEAN A. LOUIS & EST. OF MS. HAZEL L. BERRYHILL | E27: REAL | F27: 520 | I27: 4050 | J27: 10950 | K27: 15000 | N27: 7500 | O27: 8100 | P27: 19800 | Q27: 27900 | T27: 3750 | U27: 12900 | V27: -3750
A28: 916-KENTUCKYST | B28: 39W201815 | C28: 2024 | D28: EST. OF MR. & MRS. JAMES L. TAYLOR JR. | E28: REAL | F28: 510 | I28: 590 | J28: 2440 | K28: 3030 | N28: 3030 | O28: 9270 | P28: 20640 | Q28: 29910 | T28: 0 | U28: 26880 | V28: -3030
A29: 821-STMAURICEAV | B29: 39W110603 | C29: 2024 | D29: EST. OF MS. JEANETTE T. WILLIAMS, C/O ANTOINETTE V. WILLIAMS | E29: REAL | F29: 510 | I29: 350 | J29: 4250 | K29: 4600 | N29: 4600 | O29: 1510 | P29: 9270 | Q29: 10780 | T29: 0 | U29: 6180 | V29: -4600
A30: 11260-NOTAWAYLN | B30: 39W086006 | C30: 2024 | D30: MR. & MRS. RICHARD G. BUSH | E30: REAL | F30: 510 | I30: 2200 | J30: 8300 | K30: 10500 | N30: 7500 | O30: 3670 | P30: 13710 | Q30: 17380 | T30: 7500 | U30: 6880 | V30: 0
A31: 9756-WROCKTONCR | B31: 39W043614 | C31: 2024 | D31: EST. OF MS. SHIRLEY I. BURNS BRISCOE | E31: REAL | F31: 510 | I31: 2520 | J31: 11080 | K31: 13600 | N31: 7500 | O31: 2520 | P31: 19300 | Q31: 21820 | T31: 0 | U31: 8220 | V31: -7500
A32: 2732-LAVENDERST | B32: 38W304907 | C32: 2024 | D32: EST. OF MRS. ALEIDA RAMIREZ VALDEZ, ET AL | E32: REAL | F32: 510 | I32: 630 | J32: 5870 | K32: 6500 | N32: 6500 | O32: 2160 | P32: 11290 | Q32: 13450 | T32: 0 | U32: 6950 | V32: -6500
A33: 1936-PAINTERSST | B33: 38W109612 | C33: 2024 | D33: EST. OF MR. ABRAHAM HOSSAINPOUR | E33: REAL | F33: 510 | I33: 730 | J33: 4830 | K33: 5560 | N33: 5560 | O33: 1660 | P33: 13780 | Q33: 15440 | T33: 0 | U33: 9880 | V33: -5560
A34: 2819-STANTHONYST | B34: 37W306224 | C34: 2024 | D34: EST. OF THE W & W MILES IRREVOCABLE R.E. TRUST | E34: REAL | F34: 510 | I34: 1020 | J34: 5480 | K34: 6500 | N34: 6500 | O34: 1230 | P34: 21310 | Q34: 22540 | T34: 0 | U34: 16040 | V34: -6500
A35: 2215-APTUREAUDAV | B35: 37W204419 | C35: 2024 | D35: EST. OF MR. & MRS. HARRISON BRIGHT | E35: REAL | F35: 520 | I35: 790 | J35: 7710 | K35: 8500 | N35: 7500 | O35: 950 | P35: 16760 | Q35: 17710 | T35: 0 | U35: 9210 | V35: -7500
A36: 1525-NDERBIGNYST | B36: 37W109008 | C36: 2024 | D36: EST. OF MRS. MARIE S. HENO, ET AL | E36: REAL | F36: 510 | I36: 440 | J36: 2230 | K36: 2670 | N36: 2670 | O36: 2640 | P36: 10300 | Q36: 12940 | T36: 0 | U36: 10270 | V36: -2670
A37: 8226-APPLEST | B37: 716321718 | C37: 2024 | D37: EST. OF MR. BRADDOCK CHAMBLISS | E37: REAL | F37: 520 | I37: 2300 | J37: 9350 | K37: 11650 | N37: 7500 | O37: 3460 | P37: 18120 | Q37: 21580 | T37: 0 | U37: 9930 | V37: -7500
A38: Total | I38: =SUM(I19:I37) -> 275650 | J38: =SUM(J19:J37) -> 111440 | K38: =SUM(K19:K37) -> 387090 | N38: =SUM(N19:N37) -> 89760 | O38: =SUM(O19:O37) -> 348720 | P38: =SUM(P19:P37) -> 253100 | Q38: =SUM(Q19:Q37) -> 601820 | T38: =SUM(T19:T37) -> 11250 | U38: =SUM(U19:U37) -> 466690 | V38: =SUM(V19:V37) -> -78510 | W38: Total | X38: =U38-V38 -> 545200
A41: 2819-STANTHONYST | B41: 37W306224 | C41: 2025 | D41: EST. OF THE W & W MILES IRREVOCABLE R.E. TRUST | E41: REAL | F41: 510 | I41: 1020 | J41: 5480 | K41: 6500 | N41: 6500 | O41: 1230 | P41: 21310 | Q41: 22540 | T41: 0 | U41: 16040 | V41: -6500
A42: 3728-VINCENNESPL | B42: 615109602 | C42: 2025 | D42: EST. OF MRS. AGATHA F. SUNSERI, C/O MS. A. G. VIDRINE, ET AL | E42: REAL | F42: 510 | I42: 1630 | J42: 3750 | K42: 5380 | N42: 5380 | O42: 8160 | P42: 26800 | Q42: 34960 | T42: 0 | U42: 29580 | V42: -5380
A43: 2440-DAUPHINEST | B43: 38W101413 | C43: 2025 | D43: MR. ELLIS H. CHAPPELL JR. | E43: REAL | F43: 520 | I43: 1690 | J43: 13310 | K43: 15000 | N43: 7500 | O43: 6340 | P43: 57790 | Q43: 64130 | T43: 0 | U43: 49130 | V43: -7500
A44: 1033-ALVARST | B44: 39W206322 | C44: 2025 | D44: MRS. JEAN A. LOUIS & EST. OF MS. HAZEL L. BERRYHILL | E44: REAL | F44: 520 | I44: 4050 | J44: 10950 | K44: 15000 | N44: 7500 | O44: 8100 | P44: 19800 | Q44: 27900 | T44: 3750 | U44: 12900 | V44: -3750
...

Sheet REAL SQL
A1: select T.PARID, T.ALTID, T.TAXYR, t.owner_name owner, t.ROLLTYPE, A.LUC, A.FLAG15 "DMG_FLAG", A.FLAG10 "ASMT FLAG", t.OLD_LANDASMT , T.OLD_BLDGASMT , T.OLD_LANDASMT + OLD_BLDGASMT OLD_TOTALASMT, T.OLD_HEAMT "OLD_HOMESTEAD", T.NEW_LANDASMT , T.NEW_BLDGASMT, T.NEW_LANDASMT + T.NEW_BLDGASMT NEW_TOTALASMT, T.NEW_HEAMT "NEW_HOMESTEAD", (NEW_LANDASMT + NEW_BLDGASMT) -(OLD_LANDASMT + OLD_BLDGASMT) ASMT_TOTAL_DIFF, (NEW_HEAMT - OLD_HEAMT) "HOMESTEAD_DIFF" from NOA_SUPPLEMENTAL_TAX_ROLLS_staging T LEFT JOIN ASMT A ON (T.PARID = A.PARID AND A.TAXYR = T.TAXYR AND A.CUR = 'Y' ) LEFT JOIN ALTIDINDX I ON (I.PARID = T.PARID AND I.TAXYR = T.TAXYR) LEFT JOIN OWNDAT O ON (O.PARID = T.PARID AND O.TAXYR = T.TAXYR AND O.CUR = 'Y') WHERE T.ROLLTYPE='REAL' ORDER BY T.TAXYR ;

Sheet PP DETAILS
A1: PARID | B1: OWNER_NAME | C1: NOTICE_DATE | D1: QTR | E1: TAXYR | F1: ALTID | G1: ROLLTYPE | H1: OLD_NETASMT | I1: NEW_TOTALASMT | J1: NET_ASMTDIFF | K1: REASON
E2: 2023
H3: =SUM(H2:H2) -> 0 | I3: =SUM(I2:I2) -> 0 | J3: =SUM(J2:J2) -> 0
E5: 2024
H6: =SUM(H5:H5) -> 0 | I6: =SUM(I5:I5) -> 0 | J6: =SUM(J5:J5) -> 0
A8: 1620-FRANKLINAV0000001P | B8: Y BROTHERS LLC DBA LA DIVA | C8: 46169 | D8: 2 | E8: 2025 | F8: 38P104703P | G8: PP | H8: 0 | I8: 26620 | J8: 26620 | K8: NEW BUSINESS AT LOCATION. OMITTED FROM TAX ROLLS.
H9: =SUM(H8:H8) -> 0 | I9: =SUM(I8:I8) -> 26620 | J9: =SUM(J8:J8) -> 26620
A11: 1620-FRANKLINAV0000001P | B11: Y BROTHERS LLC DBA LA DIVA | C11: 46169 | D11: 2 | E11: 2026 | F11: 38P104703P | G11: PP | H11: 0 | I11: 31940 | J11: 31940 | K11: NEW BUSINESS AT LOCATION. OMITTED FROM TAX ROLLS.
H12: =SUM(H11:H11) -> 0 | I12: =SUM(I11:I11) -> 31940 | J12: =SUM(J11:J11) -> 31940
G14: TOTAL | H14: =SUM(H12,H9,H6,H3) -> 0 | I14: =SUM(I12,I9,I6,I3) -> 58560 | J14: =SUM(J12,J9,J6,J3) -> 58560

Sheet PP SQL
A1: SELECT PARID, OWNER_NAME, TEN_DAY_NOTICE_MAILDATE NOTICE_DATE, 2 QUARTER, TAXYR, ALTID, ROLLTYPE, --OLD_LANDASMT, OLD_BLDGASMT, --OLD_LANDASMT, OLD_BLDGASMT, OLD_TOTALASMT, --OLD_HEAMT, --NEW_LANDASMT, NEW_BLDGASMT, NEW_TOTALASMT, --NEW_HEAMT, (NEW_TOTALASMT - OLD_TOTALASMT) NETASMT_DIFF, REASON --CASE WHEN TEN_DAY_NOTICE_MAILDATE < '01-JAN-2022' THEN '1' ELSE NVL(TO_CHAR (TEN_DAY_NOTICE_MAILDATE, 'Q'), '1') END QUARTER FROM NOA_SUPPLEMENTAL_TAX_ROLLS_STAGING S WHERE NVL(ROLLTYPE, 'REAL') = 'PP' --AND TEN_DAY_NOTICE_MAILDATE BETWEEN '1-APR-2022' AND '30-JUN-2022' order by taxyr, altid, parid ;
